random
SENDING MESSAGE...
msg rcv #general: /help random coin
processing command: {pf}add PM Greetings
SENDING MESSAGE...
msg rcv #general: /add PM Greetings
processing command: {pf}mods
SENDING MESSAGE...
msg rcv #general: /mods
processing command: {pf}add BSI StarkRavingMadBot
SENDING MESSAGE...
msg rcv #general: /add BSI StarkRavingMadBot
processing command: {pf}add Self-Serve Colours
SENDING MESSAGE...
msg rcv #general: /add Self-Serve Colours
processing command: {pf}add Truth Game
Traceback (most recent call last):
  File "E:\Application Documents\Git\mentionbot\mentionbot\mentionbot.py", line 148, in _on_message
    await self._bot_instances[msg.server].process_text(text, msg)
  File "E:\Application Documents\Git\mentionbot\mentionbot\serverbotinstance.py", line 285, in process_text
    await cmd_to_execute(self, right, msg, privilege_level)
  File "E:\Application Documents\Git\mentionbot\mentionbot\serverbotinstance.py", line 587, in _cmdf_add
    await new_module.activate()
  File "E:\Application Documents\Git\mentionbot\mentionbot\utils.py", line 249, in wrapper_function
    ret = await function(self, *args, **kwargs)
  File "E:\Application Documents\Git\mentionbot\mentionbot\servermodulewrapper.py", line 103, in activate
    self._module_instance = await self._module_class.get_instance(self._module_cmd_aliases, res)
  File "E:\Application Documents\Git\mentionbot\mentionbot\servermodule.py", line 51, in get_instance
    await inst._initialize(resources)
  File "E:\Application Documents\Git\mentionbot\mentionbot\servermodules\truthgame.py", line 42, in _initialize
    self._load_settings()
  File "E:\Application Documents\Git\mentionbot\mentionbot\servermodules\truthgame.py", line 54, in _load_settings
    self._enabled_channels = settings["enabled channels"]
TypeError: 'NoneType' object is not subscriptable

SENDING MESSAGE...
SENDING MESSAGE...
Exception ignored in: <generator object Queue.get at 0x0578E7B0>
Traceback (most recent call last):
  File "E:\Program Files\Python35-32\lib\asyncio\queues.py", line 170, in get
  File "E:\Program Files\Python35-32\lib\asyncio\futures.py", line 227, in cancel
  File "E:\Program Files\Python35-32\lib\asyncio\futures.py", line 242, in _schedule_callbacks
  File "E:\Program Files\Python35-32\lib\asyncio\base_events.py", line 447, in call_soon
  File "E:\Program Files\Python35-32\lib\asyncio\base_events.py", line 456, in _call_soon
  File "E:\Program Files\Python35-32\lib\asyncio\base_events.py", line 284, in _check_closed
RuntimeError: Event loop is closed
Bot terminated. Return value: 1
RECONNECT_ON_ERROR is disabled.
Bot has completed execution.